<?xml version="1.0" ?>
<sdf version="1.8">

    <world name="car_world">
        <physics name="1ms" type="ignored">
            <max_step_size>0.001</max_step_size>
            <real_time_factor>1.0</real_time_factor>
        </physics>
        <plugin
            filename="libignition-gazebo-physics-system.so"
            name="ignition::gazebo::systems::Physics">
        </plugin>
        <plugin
            filename="libignition-gazebo-user-commands-system.so"
            name="ignition::gazebo::systems::UserCommands">
        </plugin>
        <plugin
            filename="libignition-gazebo-scene-broadcaster-system.so"
            name="ignition::gazebo::systems::SceneBroadcaster">
        </plugin>
        
        <plugin
            filename="libignition-gazebo-sensors-system.so"
            name="ignition::gazebo::systems::Sensors">
            <render_engine>ogre2</render_engine>
        </plugin> 
        <light type="directional" name="sun">
            <cast_shadows>true</cast_shadows>
            <pose>0 0 10 0 0 0</pose>
            <diffuse>0.8 0.8 0.8 1</diffuse>
            <specular>0.2 0.2 0.2 1</specular>
            <attenuation>
                <range>1000</range>
                <constant>0.9</constant>
                <linear>0.01</linear>
                <quadratic>0.001</quadratic>
            </attenuation>
            <direction>-0.5 0.1 -0.9</direction>
        </light>

        <model name="ground_plane">
            <static>true</static>
            <link name="link">
                <collision name="collision">
                <geometry>
                    <plane>
                    <normal>0 0 1</normal>
                    </plane>
                </geometry>
                </collision>
                <visual name="visual">
                <geometry>
                    <plane>
                    <normal>0 0 1</normal>
                    <size>100 100</size>
                    </plane>
                </geometry>
                <material>
                    <ambient>0.8 0.8 0.8 1</ambient>
                    <diffuse>0.8 0.8 0.8 1</diffuse>
                    <specular>0.8 0.8 0.8 1</specular>
                </material>
                </visual>
            </link>
        </model>
         <model name="Marker0">
    <static>true</static>
    <link name="link">
      <visual name="visual">
        <geometry>
          <mesh>
            <uri>description://meshes/aruco_marker.png</uri>
          </mesh>
        </geometry>
      </visual>
    </link>
  </model>
        <model name = 'wall'>
            <static>true</static>
             <pose relative_to='world'>4.0 0 0 0 0 0</pose>
            <link name="link">
                <collision name="collision">
                    <inertial> <!--inertial properties of the link mass, inertia matix-->
                        <mass>1.14395</mass>
                        <inertia>
                            <ixx>0.095329</ixx>
                            <ixy>0</ixy>
                            <ixz>0</ixz>
                            <iyy>0.381317</iyy>
                            <iyz>0</iyz>
                            <izz>0.476646</izz>
                        </inertia>
                    </inertial>
                    <geometry>
                        <box> 
                        <size> 1.0 8.0 2.0</size>
                        </box>
                    </geometry>
                </collision>
                <visual name="visual">
                    <geometry>
                         <box> 
                            <size> 1.0 8.0 2.0</size>
                        </box>
                    </geometry>
                <material>
                    <ambient>1.0 0.0 0.0 1</ambient>
                    <diffuse>1.0 0.0 0.0 1</diffuse>
                    <specular>1.0 0.0 0.0 1</specular>
                </material>
                <plugin filename="ignition-gazebo-label-system" name="ignition::gazebo::systems::Label">
                    <label>10</label>
                </plugin>
                </visual>
            </link>
        </model>

       
        
<plugin filename="libignition-gazebo-triggered-publisher-system.so"
        name="ignition::gazebo::systems::TriggeredPublisher">
        <input type="ignition.msgs.Int32" topic="/keyboard/keypress">
            <match field="data">16777235</match>
        </input>
        <output type="ignition.msgs.Twist" topic="/cmd_vel">
            linear: {x: 0.5}, angular: {z: 0.0}
        </output>
</plugin>
<plugin filename="libignition-gazebo-triggered-publisher-system.so"
        name="ignition::gazebo::systems::TriggeredPublisher">
        <input type="ignition.msgs.Int32" topic="/keyboard/keypress">
            <match field="data">16777237</match>
        </input>
        <output type="ignition.msgs.Twist" topic="/cmd_vel">
            linear: {x: -0.5}, angular: {z: 0.0}
        </output>
</plugin>
 <model name='vehicle_blue' canonical_link='chassis'>
    <pose relative_to='world'>0 0 0 0 0 0</pose>
    <plugin filename="ignition-gazebo-label-system" name="ignition::gazebo::systems::Label">
        <label>10</label>
    </plugin>
    <plugin
       filename="libignition-gazebo-diff-drive-system.so"
       name="ignition::gazebo::systems::DiffDrive">
       <left_joint>left_wheel_joint</left_joint>
       <right_joint>right_wheel_joint</right_joint>
       <wheel_separation>1.2</wheel_separation>
       <wheel_radius>0.4</wheel_radius>
       <odom_publish_frequency>1</odom_publish_frequency>
       <topic>cmd_vel</topic>
    </plugin>
    <frame name="lidar_frame" attached_to='chassis'>
        <pose>0.8 0 0.5 0 0 0</pose>
    </frame>

    
    <link name='chassis'>
        <sensor name='gpu_lidar' type='gpu_lidar'>"
            <pose relative_to='lidar_frame'>0 0 0 0 0 0</pose>
            <topic>lidar</topic>
            <update_rate>10</update_rate>
            <ray>
                <scan>
                    <horizontal>
                        <samples>360</samples>
                        <resolution>1</resolution>
                        <min_angle>-1.396263</min_angle>
                        <max_angle>1.396263</max_angle>
                    </horizontal>
                    <vertical>
                        <samples>1</samples>
                        <resolution>0.01</resolution>
                        <min_angle>0</min_angle>
                        <max_angle>0</max_angle>
                    </vertical>
                </scan>
                <range>
                    <min>0.08</min>
                    <max>10.0</max>
                    <resolution>0.01</resolution>
                </range>
            </ray>
            <always_on>1</always_on>
            <visualize>true</visualize>
        </sensor>
        <sensor name="camera1" type="camera">
        <update_rate>10</update_rate>
        <pose relative_to='lidar_frame'>0 0 0 0 0 0</pose>
        <topic>/images_l16</topic>
        <camera>
          <horizontal_fov>1.05</horizontal_fov>
          <image>
            <width>256</width>
            <height>256</height>
            <format>L_INT16</format>
          </image>
          <clip>
            <near>0.1</near>
            <far>10.0</far>
          </clip>
          
        </camera>
      </sensor>

    
        <pose relative_to='__model__'>0.5 0 0.4 0 0 0</pose>
        <inertial> <!--inertial properties of the link mass, inertia matix-->
        <mass>1.14395</mass>
        <inertia>
            <ixx>0.095329</ixx>
            <ixy>0</ixy>
            <ixz>0</ixz>
            <iyy>0.381317</iyy>
            <iyz>0</iyz>
            <izz>0.476646</izz>
        </inertia>
    </inertial>
      <visual name='visual'>
        <geometry>
            <box>
                <size>2.0 1.0 0.5</size>
            </box>
        </geometry>
        <!--let's add color to our link-->
        <material>
            <ambient>0.0 0.0 1.0 1</ambient>
            <diffuse>0.0 0.0 1.0 1</diffuse>
            <specular>0.0 0.0 1.0 1</specular>
        </material>
    </visual>
            <collision name='collision'>
            <geometry>
                <box>
                    <size>2.0 1.0 0.5</size>
                </box>
            </geometry>
        </collision>
    </link>
    <link name='right_wheel'>
    <pose relative_to="chassis">-0.5 -0.6 0 -1.5707 0 0</pose> <!--angles are in radian-->
    <inertial>
        <mass>1</mass>
        <inertia>
            <ixx>0.043333</ixx>
            <ixy>0</ixy>
            <ixz>0</ixz>
            <iyy>0.043333</iyy>
            <iyz>0</iyz>
            <izz>0.08</izz>
        </inertia>
    </inertial>
    <visual name='visual'>
        <geometry>
            <cylinder>
                <radius>0.4</radius>
                <length>0.2</length>
            </cylinder>
        </geometry>
        <material>
            <ambient>1.0 0.0 0.0 1</ambient>
            <diffuse>1.0 0.0 0.0 1</diffuse>
            <specular>1.0 0.0 0.0 1</specular>
        </material>
    </visual>
    <collision name='collision'>
        <geometry>
            <cylinder>
                <radius>0.4</radius>
                <length>0.2</length>
            </cylinder>
        </geometry>
    </collision>
</link>
<link name='left_wheel'>
    <pose relative_to="chassis">-0.5 0.6 0 -1.5707 0 0</pose>
    <inertial>
        <mass>1</mass>
        <inertia>
            <ixx>0.043333</ixx>
            <ixy>0</ixy>
            <ixz>0</ixz>
            <iyy>0.043333</iyy>
            <iyz>0</iyz>
            <izz>0.08</izz>
        </inertia>
    </inertial>
        <visual name='visual'>
        <geometry>
            <cylinder>
                <radius>0.4</radius>
                <length>0.2</length>
            </cylinder>
        </geometry>
        <material>
            <ambient>1.0 0.0 0.0 1</ambient>
            <diffuse>1.0 0.0 0.0 1</diffuse>
            <specular>1.0 0.0 0.0 1</specular>
        </material>
    </visual>
    <collision name='collision'>
        <geometry>
            <cylinder>
                <radius>0.4</radius>
                <length>0.2</length>
            </cylinder>
        </geometry>
    </collision>
</link>
<frame name="caster_frame" attached_to='chassis'>
    <pose>0.8 0 -0.2 0 0 0</pose>
</frame>
<link name='caster'>
    <pose relative_to='caster_frame'/>
    <inertial>
        <mass>1</mass>
        <inertia>
            <ixx>0.016</ixx>
            <ixy>0</ixy>
            <ixz>0</ixz>
            <iyy>0.016</iyy>
            <iyz>0</iyz>
            <izz>0.016</izz>
        </inertia>
    </inertial>
    <visual name='visual'>
        <geometry>
            <sphere>
                <radius>0.2</radius>
            </sphere>
        </geometry>
        <material>
            <ambient>0.0 1 0.0 1</ambient>
            <diffuse>0.0 1 0.0 1</diffuse>
            <specular>0.0 1 0.0 1</specular>
        </material>
    </visual>
    <collision name='collision'>
        <geometry>
            <sphere>
                <radius>0.2</radius>
            </sphere>
        </geometry>
    </collision>
</link>
<joint name='left_wheel_joint' type='revolute'>
    <pose relative_to='left_wheel'/>
        <parent>chassis</parent>
    <child>left_wheel</child>
       <axis>
        <xyz expressed_in='__model__'>0 1 0</xyz> <!--can be defined as any frame or even arbitrary frames-->
        <limit>
            <lower>-1.79769e+308</lower>    <!--negative infinity-->
            <upper>1.79769e+308</upper>     <!--positive infinity-->
        </limit>
    </axis>
</joint>
<joint name='right_wheel_joint' type='revolute'>
    <pose relative_to='right_wheel'/>
    <parent>chassis</parent>
    <child>right_wheel</child>
    <axis>
        <xyz expressed_in='__model__'>0 1 0</xyz>
        <limit>
            <lower>-1.79769e+308</lower>    <!--negative infinity-->
            <upper>1.79769e+308</upper>     <!--positive infinity-->
        </limit>
    </axis>
</joint>
<joint name='caster_wheel' type='ball'>
    <parent>chassis</parent>
    <child>caster</child>
</joint>
</model>

    </world>
</sdf>